[2021-07-08 11:20:13,445] {taskinstance.py:896} INFO - Dependencies all met for <TaskInstance: bluepi_dag.upload_users_data 2021-07-08T11:20:08.080179+00:00 [queued]>
[2021-07-08 11:20:13,474] {taskinstance.py:896} INFO - Dependencies all met for <TaskInstance: bluepi_dag.upload_users_data 2021-07-08T11:20:08.080179+00:00 [queued]>
[2021-07-08 11:20:13,474] {taskinstance.py:1087} INFO - 
--------------------------------------------------------------------------------
[2021-07-08 11:20:13,474] {taskinstance.py:1088} INFO - Starting attempt 1 of 1
[2021-07-08 11:20:13,474] {taskinstance.py:1089} INFO - 
--------------------------------------------------------------------------------
[2021-07-08 11:20:13,487] {taskinstance.py:1107} INFO - Executing <Task(PostgresToGCSOperator): upload_users_data> on 2021-07-08T11:20:08.080179+00:00
[2021-07-08 11:20:13,493] {standard_task_runner.py:52} INFO - Started process 10299 to run task
[2021-07-08 11:20:13,503] {standard_task_runner.py:76} INFO - Running: ['***', 'tasks', 'run', 'bluepi_dag', 'upload_users_data', '2021-07-08T11:20:08.080179+00:00', '--job-id', '32', '--pool', 'default_pool', '--raw', '--subdir', 'DAGS_FOLDER/bluepi_dag.py', '--cfg-path', '/tmp/tmpi344x36c', '--error-file', '/tmp/tmp53gv_iv1']
[2021-07-08 11:20:13,507] {standard_task_runner.py:77} INFO - Job 32: Subtask upload_users_data
[2021-07-08 11:20:13,568] {logging_mixin.py:104} INFO - Running <TaskInstance: bluepi_dag.upload_users_data 2021-07-08T11:20:08.080179+00:00 [running]> on host 3cf0296804bd
[2021-07-08 11:20:13,686] {taskinstance.py:1302} INFO - Exporting the following env vars:
AIRFLOW_CTX_DAG_OWNER=natchanon
AIRFLOW_CTX_DAG_ID=bluepi_dag
AIRFLOW_CTX_TASK_ID=upload_users_data
AIRFLOW_CTX_EXECUTION_DATE=2021-07-08T11:20:08.080179+00:00
AIRFLOW_CTX_DAG_RUN_ID=manual__2021-07-08T11:20:08.080179+00:00
[2021-07-08 11:20:13,690] {sql_to_gcs.py:150} INFO - Executing query
[2021-07-08 11:20:13,705] {base.py:78} INFO - Using connection to: id: my_postgres_conn. Host: 35.247.174.171, Port: 5432, Schema: postgres, Login: exam, Password: ***, extra: {}
[2021-07-08 11:20:15,304] {sql_to_gcs.py:153} INFO - Writing local data files
[2021-07-08 11:20:15,306] {sql_to_gcs.py:202} INFO - Current file count: 1
[2021-07-08 11:20:15,308] {sql_to_gcs.py:164} INFO - Uploading 1 files to GCS.
[2021-07-08 11:20:15,434] {gcs.py:450} ERROR - Upload attempt of object: users.csv from users.csv has failed. Attempt: 1, max 1.
[2021-07-08 11:20:15,434] {taskinstance.py:1501} ERROR - Task failed with exception
Traceback (most recent call last):
  File "/home/airflow/.local/lib/python3.6/site-packages/google/cloud/storage/blob.py", line 2502, in upload_from_file
    retry=retry,
  File "/home/airflow/.local/lib/python3.6/site-packages/google/cloud/storage/blob.py", line 2304, in _do_upload
    retry=retry,
  File "/home/airflow/.local/lib/python3.6/site-packages/google/cloud/storage/blob.py", line 1825, in _do_multipart_upload
    transport, data, object_metadata, content_type, timeout=timeout
  File "/home/airflow/.local/lib/python3.6/site-packages/google/resumable_media/requests/upload.py", line 149, in transmit
    self._process_response(response)
  File "/home/airflow/.local/lib/python3.6/site-packages/google/resumable_media/_upload.py", line 116, in _process_response
    _helpers.require_status_code(response, (http_client.OK,), self._get_status_code)
  File "/home/airflow/.local/lib/python3.6/site-packages/google/resumable_media/_helpers.py", line 104, in require_status_code
    *status_codes
google.resumable_media.common.InvalidResponse: ('Request failed with status code', 404, 'Expected one of', <HTTPStatus.OK: 200>)

During handling of the above exception, another exception occurred:

Traceback (most recent call last):
  File "/home/airflow/.local/lib/python3.6/site-packages/airflow/models/taskinstance.py", line 1157, in _run_raw_task
    self._prepare_and_execute_task_with_callbacks(context, task)
  File "/home/airflow/.local/lib/python3.6/site-packages/airflow/models/taskinstance.py", line 1331, in _prepare_and_execute_task_with_callbacks
    result = self._execute_task(context, task_copy)
  File "/home/airflow/.local/lib/python3.6/site-packages/airflow/models/taskinstance.py", line 1361, in _execute_task
    result = task_copy.execute(context=context)
  File "/home/airflow/.local/lib/python3.6/site-packages/airflow/providers/google/cloud/transfers/sql_to_gcs.py", line 165, in execute
    self._upload_to_gcs(files_to_upload)
  File "/home/airflow/.local/lib/python3.6/site-packages/airflow/providers/google/cloud/transfers/sql_to_gcs.py", line 369, in _upload_to_gcs
    gzip=self.gzip if tmp_file.get('file_name') != self.schema_filename else False,
  File "/home/airflow/.local/lib/python3.6/site-packages/airflow/providers/google/cloud/hooks/gcs.py", line 480, in upload
    partial(blob.upload_from_filename, filename=filename, content_type=mime_type, timeout=timeout)
  File "/home/airflow/.local/lib/python3.6/site-packages/airflow/providers/google/cloud/hooks/gcs.py", line 452, in _call_with_retry
    raise e
  File "/home/airflow/.local/lib/python3.6/site-packages/airflow/providers/google/cloud/hooks/gcs.py", line 441, in _call_with_retry
    f()
  File "/home/airflow/.local/lib/python3.6/site-packages/google/cloud/storage/blob.py", line 2643, in upload_from_filename
    retry=retry,
  File "/home/airflow/.local/lib/python3.6/site-packages/google/cloud/storage/blob.py", line 2506, in upload_from_file
    _raise_from_invalid_response(exc)
  File "/home/airflow/.local/lib/python3.6/site-packages/google/cloud/storage/blob.py", line 4214, in _raise_from_invalid_response
    raise exceptions.from_http_status(response.status_code, message, response=response)
google.api_core.exceptions.NotFound: 404 POST https://storage.googleapis.com/upload/storage/v1/b/gs://bluepi-landing-bucket/o?uploadType=multipart: Not Found: ('Request failed with status code', 404, 'Expected one of', <HTTPStatus.OK: 200>)
[2021-07-08 11:20:15,440] {taskinstance.py:1551} INFO - Marking task as FAILED. dag_id=bluepi_dag, task_id=upload_users_data, execution_date=20210708T112008, start_date=20210708T112013, end_date=20210708T112015
[2021-07-08 11:20:15,489] {local_task_job.py:151} INFO - Task exited with return code 1
