[2021-07-08 08:04:08,589] {taskinstance.py:896} INFO - Dependencies all met for <TaskInstance: bluepi_dag.query_users_data 2021-07-08T08:04:06.441071+00:00 [queued]>
[2021-07-08 08:04:08,608] {taskinstance.py:896} INFO - Dependencies all met for <TaskInstance: bluepi_dag.query_users_data 2021-07-08T08:04:06.441071+00:00 [queued]>
[2021-07-08 08:04:08,608] {taskinstance.py:1087} INFO - 
--------------------------------------------------------------------------------
[2021-07-08 08:04:08,609] {taskinstance.py:1088} INFO - Starting attempt 1 of 1
[2021-07-08 08:04:08,609] {taskinstance.py:1089} INFO - 
--------------------------------------------------------------------------------
[2021-07-08 08:04:08,621] {taskinstance.py:1107} INFO - Executing <Task(PostgresOperator): query_users_data> on 2021-07-08T08:04:06.441071+00:00
[2021-07-08 08:04:08,625] {standard_task_runner.py:52} INFO - Started process 3681 to run task
[2021-07-08 08:04:08,633] {standard_task_runner.py:76} INFO - Running: ['***', 'tasks', 'run', 'bluepi_dag', 'query_users_data', '2021-07-08T08:04:06.441071+00:00', '--job-id', '7', '--pool', 'default_pool', '--raw', '--subdir', 'DAGS_FOLDER/bluepi_dag.py', '--cfg-path', '/tmp/tmpdsri8z4v', '--error-file', '/tmp/tmp_9a3sz7p']
[2021-07-08 08:04:08,634] {standard_task_runner.py:77} INFO - Job 7: Subtask query_users_data
[2021-07-08 08:04:08,689] {logging_mixin.py:104} INFO - Running <TaskInstance: bluepi_dag.query_users_data 2021-07-08T08:04:06.441071+00:00 [running]> on host 60b99d043243
[2021-07-08 08:04:08,745] {taskinstance.py:1302} INFO - Exporting the following env vars:
AIRFLOW_CTX_DAG_OWNER=natchanon
AIRFLOW_CTX_DAG_ID=bluepi_dag
AIRFLOW_CTX_TASK_ID=query_users_data
AIRFLOW_CTX_EXECUTION_DATE=2021-07-08T08:04:06.441071+00:00
AIRFLOW_CTX_DAG_RUN_ID=manual__2021-07-08T08:04:06.441071+00:00
[2021-07-08 08:04:08,745] {postgres.py:68} INFO - Executing: 
            SELECT * FROM users;
        
[2021-07-08 08:04:08,757] {base.py:78} INFO - Using connection to: id: my_postgres_conn. Host: 35.247.174.171, Port: 5432, Schema: , Login: exam, Password: ***, extra: {}
[2021-07-08 08:04:09,966] {taskinstance.py:1501} ERROR - Task failed with exception
Traceback (most recent call last):
  File "/home/airflow/.local/lib/python3.6/site-packages/airflow/models/taskinstance.py", line 1157, in _run_raw_task
    self._prepare_and_execute_task_with_callbacks(context, task)
  File "/home/airflow/.local/lib/python3.6/site-packages/airflow/models/taskinstance.py", line 1331, in _prepare_and_execute_task_with_callbacks
    result = self._execute_task(context, task_copy)
  File "/home/airflow/.local/lib/python3.6/site-packages/airflow/models/taskinstance.py", line 1361, in _execute_task
    result = task_copy.execute(context=context)
  File "/home/airflow/.local/lib/python3.6/site-packages/airflow/providers/postgres/operators/postgres.py", line 70, in execute
    self.hook.run(self.sql, self.autocommit, parameters=self.parameters)
  File "/home/airflow/.local/lib/python3.6/site-packages/airflow/hooks/dbapi.py", line 177, in run
    with closing(self.get_conn()) as conn:
  File "/home/airflow/.local/lib/python3.6/site-packages/airflow/providers/postgres/hooks/postgres.py", line 115, in get_conn
    self.conn = psycopg2.connect(**conn_args)
  File "/home/airflow/.local/lib/python3.6/site-packages/psycopg2/__init__.py", line 122, in connect
    conn = _connect(dsn, connection_factory=connection_factory, **kwasync)
psycopg2.OperationalError: FATAL:  database "exam" does not exist

[2021-07-08 08:04:09,968] {taskinstance.py:1551} INFO - Marking task as FAILED. dag_id=bluepi_dag, task_id=query_users_data, execution_date=20210708T080406, start_date=20210708T080408, end_date=20210708T080409
[2021-07-08 08:04:10,052] {local_task_job.py:151} INFO - Task exited with return code 1
