[2021-07-08 13:30:38,530] {taskinstance.py:896} INFO - Dependencies all met for <TaskInstance: bluepi_dag.upload_user_log_to_GCS 2021-07-08T13:30:23.459508+00:00 [queued]>
[2021-07-08 13:30:38,549] {taskinstance.py:896} INFO - Dependencies all met for <TaskInstance: bluepi_dag.upload_user_log_to_GCS 2021-07-08T13:30:23.459508+00:00 [queued]>
[2021-07-08 13:30:38,549] {taskinstance.py:1087} INFO - 
--------------------------------------------------------------------------------
[2021-07-08 13:30:38,549] {taskinstance.py:1088} INFO - Starting attempt 1 of 1
[2021-07-08 13:30:38,549] {taskinstance.py:1089} INFO - 
--------------------------------------------------------------------------------
[2021-07-08 13:30:38,558] {taskinstance.py:1107} INFO - Executing <Task(PythonOperator): upload_user_log_to_GCS> on 2021-07-08T13:30:23.459508+00:00
[2021-07-08 13:30:38,563] {standard_task_runner.py:52} INFO - Started process 19049 to run task
[2021-07-08 13:30:38,569] {standard_task_runner.py:76} INFO - Running: ['***', 'tasks', 'run', 'bluepi_dag', 'upload_user_log_to_GCS', '2021-07-08T13:30:23.459508+00:00', '--job-id', '159', '--pool', 'default_pool', '--raw', '--subdir', 'DAGS_FOLDER/bluepi_dag.py', '--cfg-path', '/tmp/tmp2xo6shkm', '--error-file', '/tmp/tmpm0ad26ry']
[2021-07-08 13:30:38,575] {standard_task_runner.py:77} INFO - Job 159: Subtask upload_user_log_to_GCS
[2021-07-08 13:30:38,625] {logging_mixin.py:104} INFO - Running <TaskInstance: bluepi_dag.upload_user_log_to_GCS 2021-07-08T13:30:23.459508+00:00 [running]> on host 3cf0296804bd
[2021-07-08 13:30:38,680] {taskinstance.py:1302} INFO - Exporting the following env vars:
AIRFLOW_CTX_DAG_OWNER=natchanon
AIRFLOW_CTX_DAG_ID=bluepi_dag
AIRFLOW_CTX_TASK_ID=upload_user_log_to_GCS
AIRFLOW_CTX_EXECUTION_DATE=2021-07-08T13:30:23.459508+00:00
AIRFLOW_CTX_DAG_RUN_ID=manual__2021-07-08T13:30:23.459508+00:00
[2021-07-08 13:30:38,682] {logging_mixin.py:104} INFO - exam-de-natchanon
[2021-07-08 13:30:38,683] {logging_mixin.py:104} INFO - gs://bluepi-landing-bucket
[2021-07-08 13:30:38,684] {logging_mixin.py:104} INFO - /opt/***/dags/user_log_export_cleaned.csv
[2021-07-08 13:30:38,755] {taskinstance.py:1501} ERROR - Task failed with exception
Traceback (most recent call last):
  File "/home/airflow/.local/lib/python3.6/site-packages/google/cloud/storage/blob.py", line 2502, in upload_from_file
    retry=retry,
  File "/home/airflow/.local/lib/python3.6/site-packages/google/cloud/storage/blob.py", line 2304, in _do_upload
    retry=retry,
  File "/home/airflow/.local/lib/python3.6/site-packages/google/cloud/storage/blob.py", line 1825, in _do_multipart_upload
    transport, data, object_metadata, content_type, timeout=timeout
  File "/home/airflow/.local/lib/python3.6/site-packages/google/resumable_media/requests/upload.py", line 149, in transmit
    self._process_response(response)
  File "/home/airflow/.local/lib/python3.6/site-packages/google/resumable_media/_upload.py", line 116, in _process_response
    _helpers.require_status_code(response, (http_client.OK,), self._get_status_code)
  File "/home/airflow/.local/lib/python3.6/site-packages/google/resumable_media/_helpers.py", line 104, in require_status_code
    *status_codes
google.resumable_media.common.InvalidResponse: ('Request failed with status code', 403, 'Expected one of', <HTTPStatus.OK: 200>)

During handling of the above exception, another exception occurred:

Traceback (most recent call last):
  File "/home/airflow/.local/lib/python3.6/site-packages/airflow/models/taskinstance.py", line 1157, in _run_raw_task
    self._prepare_and_execute_task_with_callbacks(context, task)
  File "/home/airflow/.local/lib/python3.6/site-packages/airflow/models/taskinstance.py", line 1331, in _prepare_and_execute_task_with_callbacks
    result = self._execute_task(context, task_copy)
  File "/home/airflow/.local/lib/python3.6/site-packages/airflow/models/taskinstance.py", line 1361, in _execute_task
    result = task_copy.execute(context=context)
  File "/home/airflow/.local/lib/python3.6/site-packages/airflow/operators/python.py", line 150, in execute
    return_value = self.execute_callable()
  File "/home/airflow/.local/lib/python3.6/site-packages/airflow/operators/python.py", line 161, in execute_callable
    return self.python_callable(*self.op_args, **self.op_kwargs)
  File "/opt/airflow/dags/bluepi_dag.py", line 53, in _upload_to_gcs
    blob.upload_from_filename(source_file_name)
  File "/home/airflow/.local/lib/python3.6/site-packages/google/cloud/storage/blob.py", line 2643, in upload_from_filename
    retry=retry,
  File "/home/airflow/.local/lib/python3.6/site-packages/google/cloud/storage/blob.py", line 2506, in upload_from_file
    _raise_from_invalid_response(exc)
  File "/home/airflow/.local/lib/python3.6/site-packages/google/cloud/storage/blob.py", line 4214, in _raise_from_invalid_response
    raise exceptions.from_http_status(response.status_code, message, response=response)
google.api_core.exceptions.Forbidden: 403 POST https://storage.googleapis.com/upload/storage/v1/b/bluepi-landing-bucket/o?uploadType=multipart: {
  "error": {
    "code": 403,
    "message": "Insufficient Permission",
    "errors": [
      {
        "message": "Insufficient Permission",
        "domain": "global",
        "reason": "insufficientPermissions"
      }
    ]
  }
}
: ('Request failed with status code', 403, 'Expected one of', <HTTPStatus.OK: 200>)
[2021-07-08 13:30:38,759] {taskinstance.py:1551} INFO - Marking task as FAILED. dag_id=bluepi_dag, task_id=upload_user_log_to_GCS, execution_date=20210708T133023, start_date=20210708T133038, end_date=20210708T133038
[2021-07-08 13:30:38,819] {local_task_job.py:151} INFO - Task exited with return code 1
