[2021-07-08 07:46:01,115] {taskinstance.py:896} INFO - Dependencies all met for <TaskInstance: bluepi_dag.query_user_log_data 2021-07-08T07:45:58.621462+00:00 [queued]>
[2021-07-08 07:46:01,136] {taskinstance.py:896} INFO - Dependencies all met for <TaskInstance: bluepi_dag.query_user_log_data 2021-07-08T07:45:58.621462+00:00 [queued]>
[2021-07-08 07:46:01,137] {taskinstance.py:1087} INFO - 
--------------------------------------------------------------------------------
[2021-07-08 07:46:01,137] {taskinstance.py:1088} INFO - Starting attempt 1 of 1
[2021-07-08 07:46:01,137] {taskinstance.py:1089} INFO - 
--------------------------------------------------------------------------------
[2021-07-08 07:46:01,146] {taskinstance.py:1107} INFO - Executing <Task(PostgresOperator): query_user_log_data> on 2021-07-08T07:45:58.621462+00:00
[2021-07-08 07:46:01,151] {standard_task_runner.py:52} INFO - Started process 2493 to run task
[2021-07-08 07:46:01,158] {standard_task_runner.py:76} INFO - Running: ['***', 'tasks', 'run', 'bluepi_dag', 'query_user_log_data', '2021-07-08T07:45:58.621462+00:00', '--job-id', '3', '--pool', 'default_pool', '--raw', '--subdir', 'DAGS_FOLDER/bluepi_dag.py', '--cfg-path', '/tmp/tmp3brq7lce', '--error-file', '/tmp/tmprfdi35_8']
[2021-07-08 07:46:01,159] {standard_task_runner.py:77} INFO - Job 3: Subtask query_user_log_data
[2021-07-08 07:46:01,216] {logging_mixin.py:104} INFO - Running <TaskInstance: bluepi_dag.query_user_log_data 2021-07-08T07:45:58.621462+00:00 [running]> on host 60b99d043243
[2021-07-08 07:46:01,311] {taskinstance.py:1302} INFO - Exporting the following env vars:
AIRFLOW_CTX_DAG_OWNER=natchanon
AIRFLOW_CTX_DAG_ID=bluepi_dag
AIRFLOW_CTX_TASK_ID=query_user_log_data
AIRFLOW_CTX_EXECUTION_DATE=2021-07-08T07:45:58.621462+00:00
AIRFLOW_CTX_DAG_RUN_ID=manual__2021-07-08T07:45:58.621462+00:00
[2021-07-08 07:46:01,312] {postgres.py:68} INFO - Executing: 
            SELECT * FROM user_log;
        
[2021-07-08 07:46:01,323] {base.py:78} INFO - Using connection to: id: my_postgres_conn. Host: 35.247.174.171, Port: 5432, Schema: , Login: exam, Password: ***, extra: {}
[2021-07-08 07:46:03,056] {taskinstance.py:1501} ERROR - Task failed with exception
Traceback (most recent call last):
  File "/home/airflow/.local/lib/python3.6/site-packages/airflow/models/taskinstance.py", line 1157, in _run_raw_task
    self._prepare_and_execute_task_with_callbacks(context, task)
  File "/home/airflow/.local/lib/python3.6/site-packages/airflow/models/taskinstance.py", line 1331, in _prepare_and_execute_task_with_callbacks
    result = self._execute_task(context, task_copy)
  File "/home/airflow/.local/lib/python3.6/site-packages/airflow/models/taskinstance.py", line 1361, in _execute_task
    result = task_copy.execute(context=context)
  File "/home/airflow/.local/lib/python3.6/site-packages/airflow/providers/postgres/operators/postgres.py", line 70, in execute
    self.hook.run(self.sql, self.autocommit, parameters=self.parameters)
  File "/home/airflow/.local/lib/python3.6/site-packages/airflow/hooks/dbapi.py", line 177, in run
    with closing(self.get_conn()) as conn:
  File "/home/airflow/.local/lib/python3.6/site-packages/airflow/providers/postgres/hooks/postgres.py", line 115, in get_conn
    self.conn = psycopg2.connect(**conn_args)
  File "/home/airflow/.local/lib/python3.6/site-packages/psycopg2/__init__.py", line 122, in connect
    conn = _connect(dsn, connection_factory=connection_factory, **kwasync)
psycopg2.OperationalError: FATAL:  password authentication failed for user "exam"
FATAL:  password authentication failed for user "exam"

[2021-07-08 07:46:03,060] {taskinstance.py:1551} INFO - Marking task as FAILED. dag_id=bluepi_dag, task_id=query_user_log_data, execution_date=20210708T074558, start_date=20210708T074601, end_date=20210708T074603
[2021-07-08 07:46:03,141] {local_task_job.py:151} INFO - Task exited with return code 1
