[2021-07-08 12:15:36,467] {taskinstance.py:896} INFO - Dependencies all met for <TaskInstance: bluepi_dag.users_to_csv 2021-07-08T12:15:24.497141+00:00 [queued]>
[2021-07-08 12:15:36,489] {taskinstance.py:896} INFO - Dependencies all met for <TaskInstance: bluepi_dag.users_to_csv 2021-07-08T12:15:24.497141+00:00 [queued]>
[2021-07-08 12:15:36,490] {taskinstance.py:1087} INFO - 
--------------------------------------------------------------------------------
[2021-07-08 12:15:36,490] {taskinstance.py:1088} INFO - Starting attempt 1 of 1
[2021-07-08 12:15:36,490] {taskinstance.py:1089} INFO - 
--------------------------------------------------------------------------------
[2021-07-08 12:15:36,500] {taskinstance.py:1107} INFO - Executing <Task(PythonOperator): users_to_csv> on 2021-07-08T12:15:24.497141+00:00
[2021-07-08 12:15:36,506] {standard_task_runner.py:52} INFO - Started process 14018 to run task
[2021-07-08 12:15:36,517] {standard_task_runner.py:76} INFO - Running: ['***', 'tasks', 'run', 'bluepi_dag', 'users_to_csv', '2021-07-08T12:15:24.497141+00:00', '--job-id', '88', '--pool', 'default_pool', '--raw', '--subdir', 'DAGS_FOLDER/bluepi_dag.py', '--cfg-path', '/tmp/tmpb54rzbrc', '--error-file', '/tmp/tmp3juep1su']
[2021-07-08 12:15:36,521] {standard_task_runner.py:77} INFO - Job 88: Subtask users_to_csv
[2021-07-08 12:15:36,584] {logging_mixin.py:104} INFO - Running <TaskInstance: bluepi_dag.users_to_csv 2021-07-08T12:15:24.497141+00:00 [running]> on host 3cf0296804bd
[2021-07-08 12:15:36,649] {taskinstance.py:1302} INFO - Exporting the following env vars:
AIRFLOW_CTX_DAG_OWNER=natchanon
AIRFLOW_CTX_DAG_ID=bluepi_dag
AIRFLOW_CTX_TASK_ID=users_to_csv
AIRFLOW_CTX_EXECUTION_DATE=2021-07-08T12:15:24.497141+00:00
AIRFLOW_CTX_DAG_RUN_ID=manual__2021-07-08T12:15:24.497141+00:00
[2021-07-08 12:15:36,652] {taskinstance.py:1501} ERROR - Task failed with exception
Traceback (most recent call last):
  File "/home/airflow/.local/lib/python3.6/site-packages/airflow/models/taskinstance.py", line 1157, in _run_raw_task
    self._prepare_and_execute_task_with_callbacks(context, task)
  File "/home/airflow/.local/lib/python3.6/site-packages/airflow/models/taskinstance.py", line 1331, in _prepare_and_execute_task_with_callbacks
    result = self._execute_task(context, task_copy)
  File "/home/airflow/.local/lib/python3.6/site-packages/airflow/models/taskinstance.py", line 1361, in _execute_task
    result = task_copy.execute(context=context)
  File "/home/airflow/.local/lib/python3.6/site-packages/airflow/operators/python.py", line 150, in execute
    return_value = self.execute_callable()
  File "/home/airflow/.local/lib/python3.6/site-packages/airflow/operators/python.py", line 161, in execute_callable
    return self.python_callable(*self.op_args, **self.op_kwargs)
  File "/opt/airflow/dags/bluepi_dag.py", line 37, in _transform_to_csv
    df = pd.read_csv(f'{DAGS_FOLDER}/{table}_export', sep='\t', header=None)
NameError: name 'pd' is not defined
[2021-07-08 12:15:36,654] {taskinstance.py:1551} INFO - Marking task as FAILED. dag_id=bluepi_dag, task_id=users_to_csv, execution_date=20210708T121524, start_date=20210708T121536, end_date=20210708T121536
[2021-07-08 12:15:36,699] {local_task_job.py:151} INFO - Task exited with return code 1
