[2021-07-08 11:17:20,330] {taskinstance.py:896} INFO - Dependencies all met for <TaskInstance: bluepi_dag.upload_users_data 2021-07-08T11:17:15.067908+00:00 [queued]>
[2021-07-08 11:17:20,350] {taskinstance.py:896} INFO - Dependencies all met for <TaskInstance: bluepi_dag.upload_users_data 2021-07-08T11:17:15.067908+00:00 [queued]>
[2021-07-08 11:17:20,350] {taskinstance.py:1087} INFO - 
--------------------------------------------------------------------------------
[2021-07-08 11:17:20,351] {taskinstance.py:1088} INFO - Starting attempt 1 of 1
[2021-07-08 11:17:20,351] {taskinstance.py:1089} INFO - 
--------------------------------------------------------------------------------
[2021-07-08 11:17:20,361] {taskinstance.py:1107} INFO - Executing <Task(PostgresToGCSOperator): upload_users_data> on 2021-07-08T11:17:15.067908+00:00
[2021-07-08 11:17:20,367] {standard_task_runner.py:52} INFO - Started process 10090 to run task
[2021-07-08 11:17:20,374] {standard_task_runner.py:76} INFO - Running: ['***', 'tasks', 'run', 'bluepi_dag', 'upload_users_data', '2021-07-08T11:17:15.067908+00:00', '--job-id', '28', '--pool', 'default_pool', '--raw', '--subdir', 'DAGS_FOLDER/bluepi_dag.py', '--cfg-path', '/tmp/tmpqooqwvq7', '--error-file', '/tmp/tmp6mzg3c4i']
[2021-07-08 11:17:20,378] {standard_task_runner.py:77} INFO - Job 28: Subtask upload_users_data
[2021-07-08 11:17:20,435] {logging_mixin.py:104} INFO - Running <TaskInstance: bluepi_dag.upload_users_data 2021-07-08T11:17:15.067908+00:00 [running]> on host 3cf0296804bd
[2021-07-08 11:17:20,496] {taskinstance.py:1302} INFO - Exporting the following env vars:
AIRFLOW_CTX_DAG_OWNER=natchanon
AIRFLOW_CTX_DAG_ID=bluepi_dag
AIRFLOW_CTX_TASK_ID=upload_users_data
AIRFLOW_CTX_EXECUTION_DATE=2021-07-08T11:17:15.067908+00:00
AIRFLOW_CTX_DAG_RUN_ID=manual__2021-07-08T11:17:15.067908+00:00
[2021-07-08 11:17:20,499] {sql_to_gcs.py:150} INFO - Executing query
[2021-07-08 11:17:20,510] {base.py:78} INFO - Using connection to: id: my_postgres_conn. Host: 35.247.174.171, Port: 5432, Schema: postgres, Login: exam, Password: ***, extra: {}
[2021-07-08 11:17:22,008] {sql_to_gcs.py:153} INFO - Writing local data files
[2021-07-08 11:17:22,009] {sql_to_gcs.py:202} INFO - Current file count: 1
[2021-07-08 11:17:22,011] {sql_to_gcs.py:164} INFO - Uploading 1 files to GCS.
[2021-07-08 11:17:22,038] {taskinstance.py:1501} ERROR - Task failed with exception
Traceback (most recent call last):
  File "/home/airflow/.local/lib/python3.6/site-packages/airflow/models/taskinstance.py", line 1157, in _run_raw_task
    self._prepare_and_execute_task_with_callbacks(context, task)
  File "/home/airflow/.local/lib/python3.6/site-packages/airflow/models/taskinstance.py", line 1331, in _prepare_and_execute_task_with_callbacks
    result = self._execute_task(context, task_copy)
  File "/home/airflow/.local/lib/python3.6/site-packages/airflow/models/taskinstance.py", line 1361, in _execute_task
    result = task_copy.execute(context=context)
  File "/home/airflow/.local/lib/python3.6/site-packages/airflow/providers/google/cloud/transfers/sql_to_gcs.py", line 165, in execute
    self._upload_to_gcs(files_to_upload)
  File "/home/airflow/.local/lib/python3.6/site-packages/airflow/providers/google/cloud/transfers/sql_to_gcs.py", line 369, in _upload_to_gcs
    gzip=self.gzip if tmp_file.get('file_name') != self.schema_filename else False,
  File "/home/airflow/.local/lib/python3.6/site-packages/airflow/providers/google/cloud/hooks/gcs.py", line 459, in upload
    client = self.get_conn()
  File "/home/airflow/.local/lib/python3.6/site-packages/airflow/providers/google/cloud/hooks/gcs.py", line 151, in get_conn
    credentials=self._get_credentials(), client_info=self.client_info, project=self.project_id
  File "/home/airflow/.local/lib/python3.6/site-packages/airflow/providers/google/common/hooks/base_google.py", line 251, in _get_credentials
    credentials, _ = self._get_credentials_and_project_id()
  File "/home/airflow/.local/lib/python3.6/site-packages/airflow/providers/google/common/hooks/base_google.py", line 237, in _get_credentials_and_project_id
    delegates=delegates,
  File "/home/airflow/.local/lib/python3.6/site-packages/airflow/providers/google/cloud/utils/credentials_provider.py", line 309, in get_credentials_and_project_id
    return _CredentialProvider(*args, **kwargs).get_credentials_and_project()
  File "/home/airflow/.local/lib/python3.6/site-packages/airflow/providers/google/cloud/utils/credentials_provider.py", line 238, in get_credentials_and_project
    credentials, project_id = self._get_credentials_using_key_path()
  File "/home/airflow/.local/lib/python3.6/site-packages/airflow/providers/google/cloud/utils/credentials_provider.py", line 286, in _get_credentials_using_key_path
    self.key_path, scopes=self.scopes
  File "/home/airflow/.local/lib/python3.6/site-packages/google/oauth2/service_account.py", line 238, in from_service_account_file
    filename, require=["client_email", "token_uri"]
  File "/home/airflow/.local/lib/python3.6/site-packages/google/auth/_service_account_info.py", line 72, in from_filename
    with io.open(filename, "r", encoding="utf-8") as json_file:
FileNotFoundError: [Errno 2] No such file or directory: '/opt/airflow/credentials/sa.json'
[2021-07-08 11:17:22,043] {taskinstance.py:1551} INFO - Marking task as FAILED. dag_id=bluepi_dag, task_id=upload_users_data, execution_date=20210708T111715, start_date=20210708T111720, end_date=20210708T111722
[2021-07-08 11:17:22,117] {local_task_job.py:151} INFO - Task exited with return code 1
